<?xml version="1.0"?>
<robot name="simple_robot">

    <!-- here is just the common materials used to paint the robot -->
    <material name="red">
        <color rgba="1.0 0.0 0.0 1.0"/>
    </material>
    <material name="transparent_blue">
        <color rgba="0.0 0.0 1.0 0.50"/>
    </material>
    <material name="black">
        <color rgba="0.0 0.0 0.0 1.0"/>
    </material>
    <material name="white">
        <color rgba="1.0 1.0 1.0 1.0"/>
    </material>
    <material name="green">
        <color rgba="0.0 1.0 0.0 1.0"/>
    </material>
    <material name="blue">
        <color rgba="0.0 0.0 1.0 1.0"/>
    </material>
    <material name="yellow">
        <color rgba="1.0 1.0 0.0 1.0"/>
    </material>


    <!--  here start the structure of the robot-->
    <!-- The base_link is actually the global frame for other frames -->
    <link name="base_link">
    </link>

    <!--  *************** Chassis *************** -->
    <link name="chassis">
        <visual>
            <origin xyz="0 0 0" rpy="1.57 0 3.14"/> 
            <geometry>
                <!-- Replace box with the STL file -->
                 <mesh filename="package://robot_description/meshes/chassisWithMotor.STL" scale="0.001 0.001 0.001"/>
            </geometry>
            <material name="blue"/>                                              
        </visual>
        <collision>
            <geometry>
                <!-- Use the same STL file for collision -->
                <mesh filename="package://robot_description/meshes/chassisWithMotor.STL" scale="0.001 0.001 0.001"/>
            </geometry>
        </collision>  
        <inertial>
            <mass value="1.0"/>
            <origin xyz="0 0 0" rpy="0 0 0"/>
            <inertia ixx="0.01" ixy="0.0" ixz="0.0" iyy="0.01" iyz="0.0" izz="0.01"/>
        </inertial>
    </link> 
    <!--  *********************** base_link to chassis joint ****************** -->
    <joint name="base_to_chassis_joint" type="fixed">
        <parent link="base_link"/>
        <child link="chassis"/>
        <origin xyz="0 0 0.017" rpy="0 0 0"/>
    </joint>

    <!-- ************************ Here comes the right wheel ******************  -->
    <link name="right_wheel">
        <visual>
            <!-- the origin here defines the xyz and rpy positon of the coordinate system of right wheel-->
            <origin xyz="0 0 0" rpy="0 0 0"/> 
            <geometry>
                <!--  the STL file -->
                 <mesh filename="package://robot_description/meshes/Wheel.STL" scale="0.001 0.001 0.001"/>
            </geometry>
            <material name="green"/>                                             
        </visual>
        <collision>
            <geometry>
                <!-- Use the same STL file for collision -->
                <mesh filename="package://robot_description/meshes/Wheel.STL" scale="0.001 0.001 0.001"/>
            </geometry>
        </collision>  
        <inertial>
            <mass value="1.0"/>
            <origin xyz="0 0 0" rpy="0 0 0"/>
            <inertia ixx="0.01" ixy="0.0" ixz="0.0" iyy="0.01" iyz="0.0" izz="0.01"/>
        </inertial>
    </link> 
    <!--  Here comes the right wheel joint -->
    <joint name="chassis_right_Wheel_joint" type="continuous">
        <parent link="base_link"/>
        <child link="right_wheel"/>
        <origin xyz="0 -0.080 0" rpy="1.57 0 0"/>
        <axis xyz="0 0 1"/>
    </joint>




    <!-- *********************** Here comes the left wheel ******************** -->
    <link name="left_wheel">
        <visual>
            <!-- the origin here defines the xyz and rpy positon of the coordinate system of left wheel-->
            <origin xyz="0 0 0" rpy="3.14 0 0"/> 
            <geometry>
                <!--  the STL file -->
                 <mesh filename="package://robot_description/meshes/Wheel.STL" scale="0.001 0.001 0.001"/>
            </geometry>
            <material name="green"/>                                             
        </visual>
        <collision>
            <geometry>
                <!-- Use the same STL file for collision -->
                <mesh filename="package://robot_description/meshes/Wheel.STL" scale="0.001 0.001 0.001"/>
            </geometry>
        </collision>  
        <inertial>
            <mass value="1.0"/>
            <origin xyz="0 0 0" rpy="0 0 0"/>
            <inertia ixx="0.01" ixy="0.0" ixz="0.0" iyy="0.01" iyz="0.0" izz="0.01"/>
        </inertial>
    </link> 
    <!--  Here comes the left wheel joint -->
        <joint name="chassis_left_Wheel_joint" type="continuous">
        <parent link="base_link"/>
        <child link="left_wheel"/>
        <origin xyz="0 0.080 0" rpy="-1.57 -3.140 -3.14"/>
        <axis xyz="0 0 1"/>
    </joint>


 
    <!--    ******************** Lidar **********************          -->
    <link name="laser_link">
        <visual>
            <geometry>
                <!-- lazer as a box -->
                <box size="0.05 0.02 0.05"/>
            </geometry>
            <material name="white"/>
        </visual>
        <collision>
            <geometry>
                <!-- here the laser is made just as a box -->
                <box size="0.05 0.02 0.05"/>
            </geometry>
        </collision>
    </link>
    
    <!-- Lidar and its joint definition -->
    <joint name="laser_joint" type="fixed">
        <parent link="chassis"/>
        <child link="laser_link"/>
        <origin xyz="-0.05 0 0.15" rpy="0 0 0" />    
    </joint>

    <!-- **********      IMU   ********************* -->
    <link name="bno055">
    <visual>
        <geometry>
            <!-- bno055 -->
            <box size="0.02 0.02 0.02"/>
        </geometry>
        <material name="yellow"/>
    </visual>
        <collision>
            <geometry>
                <!-- collision box-->
                <box size="0.02 0.02 0.02"/>
            </geometry>
        </collision>
    </link>
    <!-- IMU and its joint definition -->

    <joint name="IMU_joint" type="fixed">
        <parent link="chassis"/>
        <child link="bno055"/>
        <origin xyz="0.01 0.048 0.085" rpy="0 0 0" />
    </joint>




</robot>